<?xml version="1.0" encoding="utf-8"?>
<robot xmlns:xacro="http://www.ros.org/wiki/xacro" name="pioneer3atRFID">
	<xacro:include filename="$(find rfid_simulator_test)/urdf/pioneer3at.xacro"/>
	<xacro:pioneer3at/>

	<link name="hokuyo">
		<collision>
			<origin xyz="0 0 0" rpy="0 0 0"/>
			<geometry>
				<box size="0.1 0.1 0.1"/>
			</geometry>
		</collision>

		<visual>
			<origin xyz="0 0 0" rpy="0 0 0"/>
			<geometry>
				<mesh filename="package://rfid_simulator_test/meshes/hokuyo.dae"/>
			</geometry>
		</visual>

		<inertial>
			<mass value="1e-5" />
			<origin xyz="0 0 0" rpy="0 0 0"/>
			<inertia ixx="1e-6" ixy="0" ixz="0" iyy="1e-6" iyz="0" izz="1e-6" />
		</inertial>
	</link>

	<joint name="hokuyo_joint" type="fixed">
		<axis xyz="0 1 0" />
		<origin xyz=".15 0 .31" rpy="0 0 0"/>
		<parent link="base_link"/>
		<child link="hokuyo"/>
	</joint>

	<gazebo reference="hokuyo">
		<sensor type="gpu_ray" name="head_hokuyo_sensor">
		<!--<sensor type="ray" name="head_hokuyo_sensor">-->
			<pose>0 0 0 0 0 0</pose>
			<visualize>true</visualize>
			<update_rate>30</update_rate>
			<ray>
				<scan>
					<horizontal>
						<samples>720</samples>
						<resolution>1</resolution>
						<min_angle>-1.570796</min_angle>
						<max_angle>1.570796</max_angle>
					</horizontal>
				</scan>
				<range>
					<min>0.30</min>
					<max>30.0</max>
					<resolution>0.01</resolution>
				</range>
				<noise>
					<type>gaussian</type>
					<!-- Noise parameters based on published spec for Hokuyo laser
					   achieving "+-30mm" accuracy at range < 10m.  A mean of 0.0m and
					   stddev of 0.01m will put 99.7% of samples within 0.03m of the true
					   reading. -->
					<mean>0.0</mean>
					<stddev>0.01</stddev>
				</noise>
			</ray>
			<plugin name="gazebo_ros_head_hokuyo_controller" filename="libgazebo_ros_gpu_laser.so">
			<!--      <plugin name="gazebo_ros_head_hokuyo_controller" filename="libgazebo_ros_laser.so">-->
				<topicName>laserscan</topicName>
				<frameName>hokuyo</frameName>
			</plugin>
		</sensor>
	</gazebo>

	<link name="rfidantenna">
		<collision>
			<origin xyz="0 0 0" rpy="0 0 0"/>
			<geometry>
				<box size="0.1 0.1 0.1"/>
			</geometry>
		</collision>

		<visual>
			<origin xyz="0 0 0" rpy="-1.570795 0 0"/>
			<geometry name="antenna_box">
				<box size = ".25 .25 .05"/>
			</geometry>
			<material name="WheelBlack">
				<color rgba="0.117 0.117 0.117 1"/>
			</material>
		</visual>

		<inertial>
			<mass value="1e-5" />
			<origin xyz="0 0 0" rpy="0 0 0"/>
			<inertia ixx="1e-6" ixy="0" ixz="0" iyy="1e-6" iyz="0" izz="1e-6" />
		</inertial>
	</link>	

	<joint name="rfidantenna_joint" type="prismatic">
		<limit lower="0.0" upper="1.0"  effort="100.0" velocity="0.1" />
		<axis xyz="0 0 1" />
		<origin xyz="0.0 0.0 1.5" rpy="0 0 0"/>
		<parent link="base_link"/>
		<child link="rfidantenna"/>
	</joint>

	<gazebo reference="rfidantenna">
		<sensor name="antenna1_robot" type="rfid">
			<plugin name="antennaPlugin" filename="libgazeboRfidAntennaPlugin.so">
				<frequency>865700000</frequency>
				<noisephi>0.1</noisephi>
				<noiserssi>0.01</noiserssi>
				<optional_distribution>none</optional_distribution>
				<optional_distribution_params>0.0 0.0</optional_distribution_params>
				<range>7</range>
				<communication_gain>3</communication_gain>
			</plugin>
			<always_on>1</always_on>
			<update_rate>15</update_rate>
			<visualize>true</visualize>
		</sensor>
	</gazebo>

	<!-- uncomment this to make the## License
Distributed under the GNU License. See LICENSE for more information. robot reader antenna move -->
	<!--
	<gazebo>
		<plugin name="move_antenna" filename="libmove_antenna.so">
			<speed>0.35</speed>
		</plugin>
	</gazebo>
	-->
</robot>
